<?xml version="1.0" encoding="utf-8"?>
<!-- This URDF was automatically created by SolidWorks to URDF Exporter! Originally created by Stephen Brawner (brawner@gmail.com) 
     Commit Version: 1.6.0-4-g7f85cfe  Build Version: 1.6.7995.38578
     For more information, please see http://wiki.ros.org/sw_urdf_exporter -->
<robot name="robot_car">
  <gazebo>
    <plugin name="differential_drive_controller" filename="libgazebo_ros_diff_drive.so">
      <!-- Plugin update rate in Hz -->
      <updateRate>10</updateRate>
      <!-- Thông tin bánh xe -->
      <leftJoint>left_wheel_joint</leftJoint>
      <rightJoint>right_wheel_joint</rightJoint>
      <wheelSeparation>0.35</wheelSeparation>
      <wheelDiameter>0.1</wheelDiameter>
      <!-- Giới hạn -->
      <wheelTorque>200</wheelTorque>
      <wheelAcceleration>10.0</wheelAcceleration>
      <!-- Output -->
      <odometryFrame>odom</odometryFrame>
      <robotBaseFrame>base_link</robotBaseFrame>
      <publishOdomTF>true</publishOdomTF>
      <publishWheelTF>true</publishWheelTF>
    </plugin>
  </gazebo>
  <gazebo>
    <plugin name="gazebo_ros_control" filename="libgazebo_ros_control.so">
      <robotNamespace>/robot_car</robotNamespace>
    </plugin>
  </gazebo>
  <gazebo reference="base_link">
    <kp>100000.0</kp>
    <kd>100.0</kd>
    <mu1>1.5</mu1>
    <mu2>1.5</mu2>
    <fdir1>1 0 0</fdir1>
    <maxVel>1.0</maxVel>
    <minDepth>0.001</minDepth>
    <material>Gazebo/Blue</material>
  </gazebo>
  <gazebo reference="right_wheel">
    <kp>100000.0</kp>
    <kd>100.0</kd>
    <mu1>1.5</mu1>
    <mu2>1.5</mu2>
    <fdir1>1 0 0</fdir1>
    <maxVel>1.0</maxVel>
    <minDepth>0.001</minDepth>
    <material>Gazebo/Yellow</material>
  </gazebo>
  <gazebo reference="left_wheel">
    <kp>100000.0</kp>
    <kd>100.0</kd>
    <mu1>1.5</mu1>
    <mu2>1.5</mu2>
    <fdir1>1 0 0</fdir1>
    <maxVel>1.0</maxVel>
    <minDepth>0.001</minDepth>
    <material>Gazebo/Yellow</material>
  </gazebo>
  <gazebo reference="caster_wheel">
    <kp>100000.0</kp>
    <kd>100.0</kd>
    <mu1>1.5</mu1>
    <mu2>1.5</mu2>
    <fdir1>1 0 0</fdir1>
    <maxVel>1.0</maxVel>
    <minDepth>0.001</minDepth>
    <material>Gazebo/Yellow</material>
  </gazebo>
  <gazebo reference="link_ydlidar">
    <kp>100000.0</kp>
    <kd>100.0</kd>
    <mu1>1.5</mu1>
    <mu2>1.5</mu2>
    <fdir1>1 0 0</fdir1>
    <maxVel>1.0</maxVel>
    <minDepth>0.001</minDepth>
    <material>Gazebo/Gray</material>
  </gazebo>
  <link name="base_link">
    <inertial>
      <origin xyz="0.00678154130032599 1.02572811355728E-11 0.049058783144438" rpy="0 0 0" />
      <mass value="0.73044118152173" />
      <inertia ixx="0.00392745212406862" ixy="-3.37182307490775E-11" ixz="0.000128556224286988" iyy="0.00654116388166114" iyz="-2.67918025679153E-17" izz="0.00775398575956591" />
    </inertial>
    <visual>
      <origin xyz="0 0 0" rpy="0 0 0" />
      <geometry>
        <mesh filename="package://robot_description/meshes/base_link.STL" />
      </geometry>
      <material name="">
        <color rgba="0.250980392156863 0.250980392156863 0.250980392156863 1" />
      </material>
    </visual>
    <collision>
      <origin xyz="0 0 0" rpy="0 0 0" />
      <geometry>
        <mesh filename="package://robot_description/meshes/base_link.STL" />
      </geometry>
    </collision>
  </link>
  <link name="right_wheel">
    <inertial>
      <origin xyz="1.02660101662932E-05 -1.28632647117266E-07 0.0103100236495261" rpy="0 0 0" />
      <mass value="0.02973385270431" />
      <inertia ixx="1.22905526652631E-05" ixy="-2.77372356712048E-10" ixz="-5.25015560687806E-12" iyy="1.22912184621518E-05" iyz="-2.7569576618242E-11" izz="2.03782430173705E-05" />
    </inertial>
    <visual>
      <origin xyz="0 0 0" rpy="0 0 0" />
      <geometry>
        <mesh filename="package://robot_description/meshes/right_wheel.STL" />
      </geometry>
      <material name="">
        <color rgba="0.792156862745098 0.819607843137255 0.933333333333333 1" />
      </material>
    </visual>
    <collision>
      <origin xyz="0 0 0" rpy="0 0 0" />
      <geometry>
        <mesh filename="package://robot_description/meshes/right_wheel.STL" />
      </geometry>
    </collision>
  </link>
  <joint name="right_wheel_joint" type="continuous">
    <origin xyz="0.043261 -0.1225 0.02" rpy="-1.5708 0 0" />
    <parent link="base_link" />
    <child link="right_wheel" />
    <axis xyz="0 0 1" />
    <dynamics damping="0.1" friction="0.1" />
  </joint>
  <link name="left_wheel">
    <inertial>
      <origin xyz="-1.0266010166321E-05 -1.28632647172777E-07 -0.0103100236495261" rpy="0 0 0" />
      <mass value="0.0297338527043098" />
      <inertia ixx="1.2290552665263E-05" ixy="2.77372356694601E-10" ixz="-5.25015560058811E-12" iyy="1.22912184621518E-05" iyz="2.75695766269738E-11" izz="2.03782430173704E-05" />
    </inertial>
    <visual>
      <origin xyz="0 0 0" rpy="0 0 0" />
      <geometry>
        <mesh filename="package://robot_description/meshes/left_wheel.STL" />
      </geometry>
      <material name="">
        <color rgba="0.792156862745098 0.819607843137255 0.933333333333333 1" />
      </material>
    </visual>
    <collision>
      <origin xyz="0 0 0" rpy="0 0 0" />
      <geometry>
        <mesh filename="package://robot_description/meshes/left_wheel.STL" />
      </geometry>
    </collision>
  </link>
  <joint name="left_wheel_joint" type="continuous">
    <origin xyz="0.043282 0.1225 0.02" rpy="-1.5708 0 0" />
    <parent link="base_link" />
    <child link="left_wheel" />
    <axis xyz="0 0 1" />
    <dynamics damping="0.1" friction="0.1" />
  </joint>
  <link name="caster_wheel">
    <inertial>
      <origin xyz="-0.16814 0.0040136 -0.0726" rpy="0 0 0" />
      <mass value="0.014137" />
      <inertia ixx="1.2723E-06" ixy="-4.9631E-24" ixz="-2.351E-38" iyy="1.2723E-06" iyz="-3.6734E-39" izz="1.2723E-06" />
    </inertial>
    <visual>
      <origin xyz="0 0 0" rpy="0 0 0" />
      <geometry>
        <mesh filename="package://robot_description/meshes/caster_wheel.STL" />
      </geometry>
      <material name="">
        <color rgba="0.79216 0.81961 0.93333 1" />
      </material>
    </visual>
    <collision>
      <origin xyz="0 0 0" rpy="0 0 0" />
      <geometry>
        <mesh filename="package://robot_description/meshes/caster_wheel.STL" />
      </geometry>
    </collision>
  </link>
  <joint name="caster_wheel_joint" type="continuous">
    <origin xyz="0.071461 -0.00080282 0.0776" rpy="0 0 0.019092" />
    <parent link="base_link" />
    <child link="caster_wheel" />
    <axis xyz="0 0 1" />
    <dynamics damping="0.1" friction="0.1" />
  </joint>
  <link name="link_ydlidar">
    <inertial>
      <origin xyz="0 0 0" rpy="0 0 0" />
      <mass value="0" />
      <inertia ixx="0" ixy="0" ixz="0" iyy="0" iyz="0" izz="0" />
    </inertial>
    <visual>
      <origin xyz="0 0 0" rpy="0 0 0" />
      <geometry>
        <mesh filename="package://robot_description/meshes/link_ydlidar.STL" />
      </geometry>
      <material name="">
        <color rgba="1 1 1 1" />
      </material>
    </visual>
    <collision>
      <origin xyz="0 0 0" rpy="0 0 0" />
      <geometry>
        <mesh filename="package://robot_description/meshes/link_ydlidar.STL" />
      </geometry>
    </collision>
  </link>
  <joint name="joint_ydlidar" type="fixed">
    <origin xyz="0.071461 -0.00080282 0.0776" rpy="0 0 0.019092" />
    <parent link="base_link" />
    <child link="link_ydlidar" />
    <axis xyz="0 0 1" />
    <dynamics damping="0.1" friction="0.1" />
  </joint>
</robot>